Workbook

Sheet INSTRUCTIVO
B2: PL-11b - Estudio de Mercado del Avalúo de Inmueble
B4: Paso del proceso | C4: 08 - Valuación de inmuebles
B5: Responsable de diligenciar | C5: Perito avaluador registrado
B6: Documento de referencia | C6: 08_VALUACION_DE_INMUEBLES.md
B7: Se convierte en | C7: Soporte del informe pericial (EN-08-01)
B9: QUE SE DEBE SOLICITAR ANTES DE DILIGENCIAR
B10: - | C10: Ofertas comparables del sector recopiladas por el perito
B11: - | C11: Portales inmobiliarios y contacto con inmobiliarias locales
B13: CODIGO DE COLORES
B14: Celda a diligenciar | C14: Usted debe escribir aquí.
B15: Celda calculada | C15: NO escribir: contiene formula. Se calcula sola.
B16: Fila de ejemplo | C16: Muestra el formato esperado. BORRELA antes de usar.
B17: Parámetro | C17: Configuracion de la entidad. Definalo una sola vez.
B19: REGLAS DE DILIGENCIAMIENTO
B20: - | C20: Registre TODAS las ofertas investigadas, incluidas las descartadas, con el motivo del descarte.
B21: - | C21: Marque incluida = NO para las ofertas atípicas por tamano o ubicación.
B22: - | C22: El valor por m2 adoptado es el promedio de las ofertas incluidas (ver hoja RESUMEN).
B23: - | C23: Un coeficiente de variación superior al 20% indica una muestra poco confiable.
B24: - | C24: No cambie los nombres de las columnas: la aplicación los usa para importar.
B25: - | C25: Fechas en formato AAAA-MM-DD. Valores en pesos, sin puntos ni simbolo $.
B26: - | C26: Si un dato no existe, deje la celda vacia. NO escriba cero ni 'NO REGISTRA'.
B27: - | C27: Borre la fila de ejemplo antes de entregar el archivo.
B29: DICCIONARIO DE COLUMNAS
B30: COLUMNA | C30: TIPO | D30: OBLIG. | E30: DESCRIPCION
B31: numero_oferta | C31: entero | D31: SI | E31: Consecutivo.
B32: direccion | C32: texto | D32: SI
B33: descripcion | C33: texto | D33: SI | E33: Caracteristicas del comparable.
B34: area_terreno_m2 | C34: número | D34: SI
B35: area_construida_m2 | C35: número | D35: no | E35: Cero si es lote sin construir.
B36: valor_ofertado | C36: moneda | D36: SI | E36: Precio de oferta publicado.
B37: factor_negociacion_pct | C37: número | D37: SI | E37: Descuento esperado en la negociacion. Ej: 0,08 = 8%.
B38: valor_depurado | C38: texto | D38: CALC | E38: CALCULADO: valor ofertado x (1 - factor de negociacion).
B39: valor_construccion | C39: moneda | D39: no | E39: Parte del valor atribuible a la construcción.
B40: valor_terreno | C40: texto | D40: CALC | E40: CALCULADO: valor depurado - valor de construcción.
B41: valor_m2_terreno | C41: texto | D41: CALC | E41: CALCULADO: valor de terreno / area de terreno.
B42: factor_homogeneizacion | C42: número | D42: no | E42: Ajuste por ubicación, tamano y topografia. 1 = sin ajuste.
B43: valor_m2_homogeneizado | C43: texto | D43: CALC | E43: CALCULADO: valor por m2 x factor de homogeneización.
B44: incluida | C44: texto | D44: SI | E44: NO para ofertas descartadas.
B45: motivo_descarte | C45: texto | D45: no | E45: Obligatorio si incluida = NO.
B46: fuente | C46: texto | D46: SI | E46: Inmobiliaria o portal.
...

Sheet OFERTAS
A1: {{ENTIDAD_RAZON_SOCIAL}}
A2: PL-11b - Estudio de Mercado del Avalúo de Inmueble
A3: FECHA DE CORTE: | B3: {{FECHA_CORTE}} | D3: SEDE:
A4: Amarillo = diligenciar | Gris = calculado, no escribir | Fila 7 = ejemplo, borrela
A6: numero_oferta | B6: direccion | C6: descripcion | D6: area_terreno_m2 | E6: area_construida_m2 | F6: valor_ofertado | G6: factor_negociacion_pct | H6: valor_depurado | I6: valor_construccion | J6: valor_terreno | K6: valor_m2_terreno | L6: factor_homogeneizacion | M6: valor_m2_homogeneizado | N6: incluida | O6: motivo_descarte | P6: fuente | Q6: link | R6: valor_para_estadistica
A7: 1 | B7: CARRERA 9 No. 9-15 | C7: Lote amplio, topografia ondulada, entorno suburbano | D7: 5510 | E7: 0 | F7: 2500000000 | G7: 0.08 | H7: =IF(OR($F7="",$G7=""),"",$F7*(1-$G7)) -> 2300000000 | I7: 0 | J7: =IF($H7="","",$H7-IF($I7="",0,$I7)) -> 2300000000 | K7: =IF(OR($J7="",$D7=0),"",$J7/$D7) -> 417422.87 | L7: 1.5731 | M7: =IF(OR($K7="",$L7=""),"",$K7*$L7) -> 656647.91 | N7: SI | P7: INMOBILIARIA LOCAL - 300 000 0000 | Q7: https://... | R7: =IF($N7="SI",$M7,"") -> 656647.91
H8: =IF(OR($F8="",$G8=""),"",$F8*(1-$G8)) | J8: =IF($H8="","",$H8-IF($I8="",0,$I8)) | K8: =IF(OR($J8="",$D8=0),"",$J8/$D8) | M8: =IF(OR($K8="",$L8=""),"",$K8*$L8) | R8: =IF($N8="SI",$M8,"")
H9: =IF(OR($F9="",$G9=""),"",$F9*(1-$G9)) | J9: =IF($H9="","",$H9-IF($I9="",0,$I9)) | K9: =IF(OR($J9="",$D9=0),"",$J9/$D9) | M9: =IF(OR($K9="",$L9=""),"",$K9*$L9) | R9: =IF($N9="SI",$M9,"")
H10: =IF(OR($F10="",$G10=""),"",$F10*(1-$G10)) | J10: =IF($H10="","",$H10-IF($I10="",0,$I10)) | K10: =IF(OR($J10="",$D10=0),"",$J10/$D10) | M10: =IF(OR($K10="",$L10=""),"",$K10*$L10) | R10: =IF($N10="SI",$M10,"")
H11: =IF(OR($F11="",$G11=""),"",$F11*(1-$G11)) | J11: =IF($H11="","",$H11-IF($I11="",0,$I11)) | K11: =IF(OR($J11="",$D11=0),"",$J11/$D11) | M11: =IF(OR($K11="",$L11=""),"",$K11*$L11) | R11: =IF($N11="SI",$M11,"")
H12: =IF(OR($F12="",$G12=""),"",$F12*(1-$G12)) | J12: =IF($H12="","",$H12-IF($I12="",0,$I12)) | K12: =IF(OR($J12="",$D12=0),"",$J12/$D12) | M12: =IF(OR($K12="",$L12=""),"",$K12*$L12) | R12: =IF($N12="SI",$M12,"")
H13: =IF(OR($F13="",$G13=""),"",$F13*(1-$G13)) | J13: =IF($H13="","",$H13-IF($I13="",0,$I13)) | K13: =IF(OR($J13="",$D13=0),"",$J13/$D13) | M13: =IF(OR($K13="",$L13=""),"",$K13*$L13) | R13: =IF($N13="SI",$M13,"")
H14: =IF(OR($F14="",$G14=""),"",$F14*(1-$G14)) | J14: =IF($H14="","",$H14-IF($I14="",0,$I14)) | K14: =IF(OR($J14="",$D14=0),"",$J14/$D14) | M14: =IF(OR($K14="",$L14=""),"",$K14*$L14) | R14: =IF($N14="SI",$M14,"")
H15: =IF(OR($F15="",$G15=""),"",$F15*(1-$G15)) | J15: =IF($H15="","",$H15-IF($I15="",0,$I15)) | K15: =IF(OR($J15="",$D15=0),"",$J15/$D15) | M15: =IF(OR($K15="",$L15=""),"",$K15*$L15) | R15: =IF($N15="SI",$M15,"")
H16: =IF(OR($F16="",$G16=""),"",$F16*(1-$G16)) | J16: =IF($H16="","",$H16-IF($I16="",0,$I16)) | K16: =IF(OR($J16="",$D16=0),"",$J16/$D16) | M16: =IF(OR($K16="",$L16=""),"",$K16*$L16) | R16: =IF($N16="SI",$M16,"")
H17: =IF(OR($F17="",$G17=""),"",$F17*(1-$G17)) | J17: =IF($H17="","",$H17-IF($I17="",0,$I17)) | K17: =IF(OR($J17="",$D17=0),"",$J17/$D17) | M17: =IF(OR($K17="",$L17=""),"",$K17*$L17) | R17: =IF($N17="SI",$M17,"")
H18: =IF(OR($F18="",$G18=""),"",$F18*(1-$G18)) | J18: =IF($H18="","",$H18-IF($I18="",0,$I18)) | K18: =IF(OR($J18="",$D18=0),"",$J18/$D18) | M18: =IF(OR($K18="",$L18=""),"",$K18*$L18) | R18: =IF($N18="SI",$M18,"")
H19: =IF(OR($F19="",$G19=""),"",$F19*(1-$G19)) | J19: =IF($H19="","",$H19-IF($I19="",0,$I19)) | K19: =IF(OR($J19="",$D19=0),"",$J19/$D19) | M19: =IF(OR($K19="",$L19=""),"",$K19*$L19) | R19: =IF($N19="SI",$M19,"")
... H157: =IF(OR($F157="",$G157=""),"",$F157*(1-$G157)) | J157: =IF($H157="","",$H157-IF($I157="",0,$I157)) | K157: =IF(OR($J157="",$D157=0),"",$J157/$D157) | M157: =IF(OR($K157="",$L157=""),"",$K157*$L157) | R157: =IF($N157="SI",$M157,"")

Sheet RESUMEN
B2: RESUMEN ESTADISTICO DEL ESTUDIO DE MERCADO
B4: Ofertas investigadas | C4: =COUNTA(OFERTAS!$A$7:$A$157) -> 1 | D4: Total de comparables registrados, incluidos los descartados.
B5: Ofertas incluidas | C5: =COUNTIF(OFERTAS!$N$7:$N$157,"SI") -> 1 | D5: Las que alimentan el promedio.
B6: Ofertas descartadas | C6: =COUNTIF(OFERTAS!$N$7:$N$157,"NO") -> 0 | D6: Deben tener motivo de descarte registrado.
B7: Media aritmética ($/m2) | C7: =IF($C$5=0,"",AVERAGE(OFERTAS!$R$7:$R$157)) -> 656647.91 | D7: Promedio de las ofertas incluidas.
B8: Desviacion estándar | C8: =IF($C$5<2,"",STDEV(OFERTAS!$R$7:$R$157)) | D8: Dispersion de la muestra.
B9: Coeficiente de variación | C9: =IF(OR($C$8="",$C$7="",$C$7=0),"",$C$8/$C$7) | D9: Desviacion / media. Por encima de 20% la muestra es poco confiable.
B10: Valor máximo ($/m2) | C10: =IF($C$5=0,"",MAX(OFERTAS!$R$7:$R$157)) -> 656647.91
B11: Valor mínimo ($/m2) | C11: =IF($C$5=0,"",MIN(OFERTAS!$R$7:$R$157)) -> 656647.91
B12: VALOR ADOPTADO POR m2 DE TERRENO | C12: =IF($C$7="","",$C$7) -> 656647.91 | D12: Se adopta la media de las ofertas incluidas. Llevelo a PL-11 columna valor_m2_terreno.
B13: Confiabilidad de la muestra | C13: =IF($C$9="","",IF($C$9<=0.2,"ACEPTABLE","REVISAR: dispersión alta")) | D13: CALCULADO a partir del coeficiente de variación.
